Workbook

Sheet Tablero
A1: TABLERO DE CRECIMIENTO — Marco YC (ERP + Agentes 2 semanas)
A2: Métricas que importan: WAU Agentes · NRR/Churn ERP · CAC vs LTV · Crecimiento WoW. Amarillo = supuestos que TÚ ajustas.
A4: SUPUESTOS DE MOTOR OUTBOUND
A5: Reps outbound (FTE humanos) | B5: 2
A6: Toques netos / día por rep (asistido por agentes) | B6: 40 | C6: 1er contacto efectivo
A7: Días hábiles / semana | B7: 5
A8: Reparto de capacidad a TMS (resto va a IPS) | B8: 0.5 | C8: %
A9: Tasa: toque → conexión con decisor | B9: 0.25 | C9: %
A10: Tasa: conexión → reunión / demo | B10: 0.2 | C10: %
A11: Tasa: reunión → piloto agente (deploy 2 sem) | B11: 0.35 | C11: %
A12: Tasa: piloto → cuenta ERP (land & expand) | B12: 0.15 | C12: %
A13: Meta de crecimiento semanal (WoW) | B13: 0.06 | C13: 5-7% objetivo PMF
A15: EMBUDO SEMANAL (capacidad total → resultados)
A16: Toques / día (todo el equipo) | B16: =B5*B6 -> 80
A17: Toques / semana | B17: =B16*B7 -> 400
A18: Conexiones con decisor / semana | B18: =B17*B9 -> 100
A19: Reuniones / demos / semana | B19: =B18*B10 -> 20
A20: Pilotos de agente / semana | B20: =B19*B11 -> 7
A21: Cuentas ERP nuevas / semana (steady-state) | B21: =B20*B12 -> 1.05
A23: COBERTURA DEL UNIVERSO
A24: Empresas TMS activas | B24: ='Universo TMS'!C25 -> 4175
A25: IPS privadas Bogotá (únicas) | B25: =IPS!B2 -> 3386
A26: Universo combinado (TMS+IPS) | B26: =B24+B25 -> 7561
A27: Semanas para 1 pasada combinada (capacidad total) | B27: =B26/B17 -> 18.9025
A28: Semanas para duplicar (a meta WoW) | B28: =LN(2)/LN(1+B13) -> 11.895661
A30: MÉTRICAS YC — DEFINICIÓN Y META
A31: Métrica | B31: Definición / fórmula | C31: Meta | D31: Por qué importa
A32: WAU Agentes | B32: Empresas que usan el agente ≥1 vez/semana | C32: crecer 6%+ WoW | D32: Valor real, no vanity
A33: NRR (ERP) | B33: (MRR inicio + expansión − contracción − churn)/MRR inicio | C33: ≥ 110% | D33: Land & expand sano
A34: Churn lógico ERP | B34: Cuentas ERP perdidas / total (mes) | C34: < 2% mensual | D34: ERP debe pegar
A35: CAC | B35: (Ventas+Mkt) / cuentas nuevas | C35: ↓ con agentes | D35: Eficiencia de capital
A36: LTV | B36: Ticket × margen bruto / churn | C36: — | D36: Techo de unit economics
A37: LTV / CAC | B37: LTV ÷ CAC | C37: ≥ 3.0x | D37: Umbral de aceleradora top
A38: Crecimiento WoW | B38: (Sem actual − previa)/previa | C38: 5–7% | D38: Velocidad a PMF
A40: UNIT ECONOMICS (ajusta amarillos)
A41: Ticket ERP mensual (COP) | B41: 2500000
A42: Margen bruto | B42: 0.75
A43: Churn mensual ERP | B43: 0.02
A44: CAC por cuenta (COP) | B44: 6000000
A45: LTV (COP) | B45: =B41*B42/B43 -> 93750000
...

Sheet Universo TMS
A1: UNIVERSO TMS — Empresas de transporte de carga habilitadas (ACTIVAS) por departamento
A2: Conteo derivado del listado de habilitación. Ordenado por tamaño; tier por concentración (80/20).
A4: # | B4: Departamento | C4: Empresas | D4: % del universo | E4: % acumulado | F4: Tier de ataque
A5: 1 | B5: Cundinamarca / Bogotá | C5: 1255 | D5: =C5/$C$25 -> 0.3005988 | E5: =D5 -> 0.3005988 | F5: Tier 1
A6: 2 | B6: Antioquia | C6: 514 | D6: =C6/$C$25 -> 0.12311377 | E6: =E5+D6 -> 0.42371257 | F6: Tier 1
A7: 3 | B7: Atlántico | C7: 315 | D7: =C7/$C$25 -> 0.075449102 | E7: =E6+D7 -> 0.49916168 | F7: Tier 1
A8: 4 | B8: Bolívar | C8: 307 | D8: =C8/$C$25 -> 0.073532934 | E8: =E7+D8 -> 0.57269461 | F8: Tier 2
A9: 5 | B9: Boyacá | C9: 307 | D9: =C9/$C$25 -> 0.073532934 | E9: =E8+D9 -> 0.64622754 | F9: Tier 2
A10: 6 | B10: Meta | C10: 274 | D10: =C10/$C$25 -> 0.065628743 | E10: =E9+D10 -> 0.71185629 | F10: Tier 2
A11: 7 | B11: Valle del Cauca | C11: 261 | D11: =C11/$C$25 -> 0.06251497 | E11: =E10+D11 -> 0.77437126 | F11: Tier 2
A12: 8 | B12: Santander | C12: 211 | D12: =C12/$C$25 -> 0.050538922 | E12: =E11+D12 -> 0.82491018 | F12: Tier 2
A13: 9 | B13: Norte de Santander | C13: 123 | D13: =C13/$C$25 -> 0.029461078 | E13: =E12+D13 -> 0.85437126 | F13: Tier 3
A14: 10 | B14: Cesar | C14: 113 | D14: =C14/$C$25 -> 0.027065868 | E14: =E13+D14 -> 0.88143713 | F14: Tier 3
A15: 11 | B15: Magdalena | C15: 111 | D15: =C15/$C$25 -> 0.026586826 | E15: =E14+D15 -> 0.90802395 | F15: Tier 3
A16: 12 | B16: Huila | C16: 108 | D16: =C16/$C$25 -> 0.025868263 | E16: =E15+D16 -> 0.93389222 | F16: Tier 3
A17: 13 | B17: Nariño | C17: 105 | D17: =C17/$C$25 -> 0.025149701 | E17: =E16+D17 -> 0.95904192 | F17: Tier 3
... A24: 20 | B24: Cauca | C24: 10 | D24: =C24/$C$25 -> 0.0023952096 | E24: =E23+D24 -> 1 | F24: Tier 3
B25: TOTAL TMS | C25: =SUM(C5:C24) -> 4175 | D25: =SUM(D5:D24) -> 1

Sheet Plan de Contacto
A1: PLAN DE CONTACTO — Metas diarias y semanales por vertical
A3: METAS GLOBALES POR VERTICAL (capacidad repartida según Tablero)
A4: Vertical | B4: Universo | C4: Meta toques/día | D4: Meta toques/semana | E4: Semanas 1 pasada | F4: Pilotos/sem (meta)
A5: TMS (transporte de carga) | B5: ='Universo TMS'!C25 -> 4175 | C5: =Tablero!B16*Tablero!B8 -> 40 | D5: =Tablero!B17*Tablero!B8 -> 200 | E5: =B5/D5 -> 20.875 | F5: =Tablero!B20*Tablero!B8 -> 3.5
A6: IPS privadas Bogotá | B6: =IPS!B2 -> 3386 | C6: =Tablero!B16*(1-Tablero!B8) -> 40 | D6: =Tablero!B17*(1-Tablero!B8) -> 200 | E6: =B6/D6 -> 16.93 | F6: =Tablero!B20*(1-Tablero!B8) -> 3.5
A7: COMBINADO (capacidad total) | B7: =B5+B6 -> 7561 | C7: =Tablero!B16 -> 80 | D7: =Tablero!B17 -> 400 | E7: =B7/D7 -> 18.9025 | F7: =Tablero!B20 -> 7
A8: Con reparto 50/50: TMS y IPS corren en paralelo. Cambia el % en Tablero para priorizar una vertical.
A10: IPS BOGOTÁ — ORDEN DE ATAQUE POR READINESS
A11: Prioridad | B11: Segmento | C11: IPS | D11: Semanas (a meta IPS)
A12: 1 | B12: A · Lista (gerente+email) → contactar YA | C12: =IPS!B3 -> 2820 | D12: =C12/D6 -> 14.1
A13: 2 | B13: B · Con canal (sin gerente) → enriquecer gerente | C13: =IPS!B4 -> 548 | D13: =C13/D6 -> 2.74
A14: 3 | B14: C · Requiere enriquecimiento (sin email/tel) | C14: =IPS!B5 -> 18 | D14: =C14/D6 -> 0.09
A16: SECUENCIA DE ATAQUE TMS (cronograma por región, a la capacidad asignada a TMS)
A17: Orden | B17: Región | C17: Empresas | D17: Días para cubrir | E17: Semana inicio | F17: Semana fin (acum.)
A18: 1 | B18: Cundinamarca / Bogotá | C18: ='Universo TMS'!C5 -> 1255 | D18: =C18/($C$5) -> 31.375 | E18: 0 | F18: =C18/$D$5 -> 6.275
A19: 2 | B19: Antioquia | C19: ='Universo TMS'!C6 -> 514 | D19: =C19/($C$5) -> 12.85 | E19: =F18 -> 6.275 | F19: =F18+C19/$D$5 -> 8.845
A20: 3 | B20: Atlántico | C20: ='Universo TMS'!C7 -> 315 | D20: =C20/($C$5) -> 7.875 | E20: =F19 -> 8.845 | F20: =F19+C20/$D$5 -> 10.42
A21: 4 | B21: Bolívar | C21: ='Universo TMS'!C8 -> 307 | D21: =C21/($C$5) -> 7.675 | E21: =F20 -> 10.42 | F21: =F20+C21/$D$5 -> 11.955
A22: 5 | B22: Boyacá | C22: ='Universo TMS'!C9 -> 307 | D22: =C22/($C$5) -> 7.675 | E22: =F21 -> 11.955 | F22: =F21+C22/$D$5 -> 13.49
A23: 6 | B23: Meta | C23: ='Universo TMS'!C10 -> 274 | D23: =C23/($C$5) -> 6.85 | E23: =F22 -> 13.49 | F23: =F22+C23/$D$5 -> 14.86
A24: 7 | B24: Valle del Cauca | C24: ='Universo TMS'!C11 -> 261 | D24: =C24/($C$5) -> 6.525 | E24: =F23 -> 14.86 | F24: =F23+C24/$D$5 -> 16.165
A25: 8 | B25: Santander | C25: ='Universo TMS'!C12 -> 211 | D25: =C25/($C$5) -> 5.275 | E25: =F24 -> 16.165 | F25: =F24+C25/$D$5 -> 17.22
A26: 9 | B26: Norte de Santander | C26: ='Universo TMS'!C13 -> 123 | D26: =C26/($C$5) -> 3.075 | E26: =F25 -> 17.22 | F26: =F25+C26/$D$5 -> 17.835
A27: 10 | B27: Cesar | C27: ='Universo TMS'!C14 -> 113 | D27: =C27/($C$5) -> 2.825 | E27: =F26 -> 17.835 | F27: =F26+C27/$D$5 -> 18.4
A28: 11 | B28: Magdalena | C28: ='Universo TMS'!C15 -> 111 | D28: =C28/($C$5) -> 2.775 | E28: =F27 -> 18.4 | F28: =F27+C28/$D$5 -> 18.955
A29: 12 | B29: Huila | C29: ='Universo TMS'!C16 -> 108 | D29: =C29/($C$5) -> 2.7 | E29: =F28 -> 18.955 | F29: =F28+C29/$D$5 -> 19.495
A30: 13 | B30: Nariño | C30: ='Universo TMS'!C17 -> 105 | D30: =C30/($C$5) -> 2.625 | E30: =F29 -> 19.495 | F30: =F29+C30/$D$5 -> 20.02
... A37: 20 | B37: Cauca | C37: ='Universo TMS'!C24 -> 10 | D37: =C37/($C$5) -> 0.25 | E37: =F36 -> 20.825 | F37: =F36+C37/$D$5 -> 20.875
B38: TOTAL | C38: =SUM(C18:C37) -> 4175 | F38: =F37 -> 20.875

Sheet CRM TMS
A1: CRM TMS — Pipeline (pega aquí el listado completo; incluye semilla enriquecida de Cundinamarca)
A3: NIT | B3: Empresa | C3: Departamento | D3: Sitio web | E3: Contacto (nombre/cargo) | F3: Email / WhatsApp | G3: LinkedIn gerente | H3: Tier | I3: Canal 1er toque | J3: Estado | K3: Fecha contacto | L3: Responsable | M3: Notas
A4: 800037047 | B4: TRANSPORTES AUTO ALFAN LTDA | C4: Cundinamarca | D4: trans-autoalfan.com | E4: Luis Alberto Zamora - Gte Operacional | F4: (601) 4118128 | H4: Tier 1 | I4: Llamada/WhatsApp | J4: Por contactar
A5: 900050309 | B5: CARGA MUDANZAS COLOMBIA S.A. | C5: Cundinamarca | D5: cargamudanzas.com | E5: Gerencia General | F5: (601) 8937660 | H5: Tier 1 | I5: Llamada | J5: Por contactar
A6: 830096376 | B6: TRANSPORTES HUMADEA LTDA. | C6: Cundinamarca | D6: humadea.com.co | E6: Gerencia / Coord. Comercial | F6: contacto@humadea.com.co | H6: Tier 1 | I6: Email | J6: Por contactar
A7: 860048617 | B7: COOP. TRANSPORTADORES DE ZIPAQUIRA | C7: Cundinamarca | D7: cootranszipa.com.co | E7: Wilmar Gomez - Pte. Consejo | F7: gerencia@cootranszipa.com.co | H7: Tier 1 | I7: Email | J7: Por contactar
A8: 860052980 | B8: SURAMERICANA DE TRANSPORTES S.A. | C8: Cundinamarca | D8: suramericanadetransportes.com | E8: Dirección Comercial | F8: Comercial@suratrans.com | H8: Tier 1 | I8: Email | J8: Por contactar
A9: 800049934 | B9: CIA. COLOMBIANA DE CARGA CONCARGA S.A. | C9: Cundinamarca | D9: concarga.co | E9: Gerencia Comercial | F9: 3164018106 | H9: Tier 1 | I9: WhatsApp | J9: Por contactar
A10: 830042504 | B10: TRANSPORTES DE CARGA NACIONAL LTDA | C10: Cundinamarca | D10: tcnltda.com | E10: Gerencia Ventas | F10: ventas@tcnltda.com | H10: Tier 1 | I10: Email | J10: Por contactar
A11: 800121921 | B11: ENERPETROL S.A. | C11: Cundinamarca | D11: enerpetrolsa.com | E11: Gerencia General | F11: gerencia@enerpetrolsa.com | H11: Tier 1 | I11: Email | J11: Por contactar
A12: 860026744 | B12: AGIL CARGO S.A.S (ALDIA) | C12: Cundinamarca | D12: aldialogistica.com | E12: Leonel Molina Varela | F12: lemolvar@gmail.com / 3164823240 | H12: Tier 1 | I12: WhatsApp | J12: Por contactar
A13: 890903501 | B13: INTERANDINA DE TRANSPORTES S.A. | C13: Cundinamarca | D13: inantra.com | E13: Gerencia General | F13: (601) 8299703 | H13: Tier 1 | I13: Llamada | J13: Por contactar
A14: 800081833 | B14: LINEAS TECNICAS DE CARGAMENTO S.A. | C14: Cundinamarca | D14: litecar.com | E14: Gerencia General | F14: (601) 8964170 | H14: Tier 1 | I14: Llamada | J14: Por contactar
A15: 860450987 | B15: TRANSPORTES JOALCO S.A. | C15: Cundinamarca | D15: transjoalco.com.co | E15: Gerencia / Servicio Cliente | F15: servicioalcliente@transjoalco.com.co | H15: Tier 1 | I15: Email | J15: Por contactar
... A21: 800185306 | B21: COLVANES S.A.S. (ENVIA) | C21: Cundinamarca | D21: envia.co | E21: Henry A. Cubides Moreno - Rep. Legal | F21: contactanos@envia.co | H21: Tier 1 | I21: Email | J21: Por contactar

Sheet IPS
A1: IPS PRIVADAS BOGOTÁ — Universo de contacto (gerente · email · teléfono ya enriquecidos)
A2: Total IPS únicas: | B2: =COUNTA($B$8:$B$100000) -> 3386
A3: A · Lista (gerente+email): | B3: =COUNTIF($H$8:$H$100000,"A*") -> 2820
A4: B · Con canal (sin gerente): | B4: =COUNTIF($H$8:$H$100000,"B*") -> 548
A5: C · Requiere enriquecimiento: | B5: =COUNTIF($H$8:$H$100000,"C*") -> 18
A6: Ordenadas por readiness (A primero). Empieza por las A.
A7: Código | B7: IPS | C7: Gerente | D7: Dirección | E7: Teléfono | F7: Email | G7: URL | H7: Readiness | I7: Canal 1er toque | J7: Estado | K7: Fecha | L7: Responsable | M7: Notas
A8: 110011953201 | B8: & ACOMPAÑAMIENTO INTEGRAL AMBULATORIO Y DOMICILIARIO | C8: HENRY ALARCON LOPEZ | D8: CALLE 119A NO 70-15 | E8: 7026848 | F8: henry.alarcon@saiadltda.com | H8: A · Lista (gerente+email) | I8: Email | J8: Por contactar
A9: 110014019201 | B9: 11:11 LOOKING GOOD TECHNOLOGIES S.A.S SIGLA 11:11 LGT | C9: Paula Andrea Puentes Guevara | D9: Carrera 19 # 84 - 17 Of 601 Consultorio 1 | E9: 3043800648 | F9: contacto@doctoreternal.com | H9: A · Lista (gerente+email) | I9: Email | J9: Por contactar
A10: 110012817401 | B10: 14-85 DENTAL SPA S.A.S | C10: BEATRIZ EUGENIA TORO PEÑA | D10: CARRERA 14 No. 85-68 OF 303 | E10: 3157056255 | F10: gerencia2@1485dentalspa.com | H10: A · Lista (gerente+email) | I10: Email | J10: Por contactar
A11: 110012817403 | B11: 14-85 DENTAL SPA SALITRE | C11: JEAN-FRANCOIS HENO | D11: Carrera 68B # 24 - 39 LOCAL 3-19 - 3-21 | E11: 3157056255 | F11: gerencia2@1485dentalspa.com | H11: A · Lista (gerente+email) | I11: Email | J11: Por contactar
A12: 110012817402 | B12: 14-85 DENTAL SPA UNICENTRO | C12: JEAN FRANCOIS MARIE HENO | D12: CL 119 #14-42 LC2 PISOS 1 y 2 | E12: 3157056255 | F12: gerencia2@1485dentalspa.com | H12: A · Lista (gerente+email) | I12: Email | J12: Por contactar
A13: 110013961501 | B13: 3D Centro Imagenes Diagnosticas | C13: LIZETH JULIANA ARENAS CARDENAS | D13: AK 9# 127B-16 LOCAL 3 | E13: 3001959807 | F13: gerencia@3dcentrodid.com | H13: A · Lista (gerente+email) | I13: Email | J13: Por contactar
A14: 110010985901 | B14: A UNO DENTAL COLOR | C14: LUIS FERNANDO ORTIZ RODRIGUEZ | D14: AC 53 # 59 03 | E14: 2220297 | F14: aunodentalcolor@hotmail.com | H14: A · Lista (gerente+email) | I14: Email | J14: Por contactar
A15: 110014000101 | B15: A&E SALUD ODONTOLOGIA | C15: ORLANDO HERRERA MESINO | D15: Calle 125 #21A-18 Piso 2 Oficina 205 Edif Foma 97 | E15: 3123529707 | F15: AESALUD@AESALUD.COM.CO | H15: A · Lista (gerente+email) | I15: Email | J15: Por contactar
A16: 110011242501 | B16: A&G SERVICIOS DE SALUD S.A.S | C16: SONIA PATRICIA CASTRO ZARATE | D16: AC 127 # 71 96 | E16: 7455901-7455902-7455905 | F16: gerencia@aygserviciosdesalud.com | H16: A · Lista (gerente+email) | I16: Email | J16: Por contactar
A17: 1100112425 | B17: A&G SERVICIOS DE SALUD S.A.S. | C17: RICHARD GOMEZ SILVA | D17: AC 127 # 71 96 | E17: 7455901-7455902-7455905 | F17: auditorensalud@aygserviciosdesalud.com | H17: A · Lista (gerente+email) | I17: Email | J17: Por contactar
A18: 1100109757 | B18: AAAA ACADEMIA ABSCRITA A ASOCIACION DE ESPECIALISTAS S.A.S | C18: VIVAS TROCHEZ ALVARO LEON | D18: AV CARACAS # 30 51 | E18: 3124354990 | F18: calidad@mascercadeusted.com-Clinicadeespecialistas2005@yahoo.es | H18: A · Lista (gerente+email) | I18: Email | J18: Por contactar
A19: 110014146301 | B19: AB ODONTOLOGIA INTEGRAL | C19: JOSE OMAIRO BUSTOS SANCHEZ | D19: DIAGONAL 23#69-11 LOCAL 2-242 | E19: 31055446905 | F19: abodontologia2242@gmail.com | H19: A · Lista (gerente+email) | I19: Email | J19: Por contactar
... A24: 1100109599 | B24: ADMINISTRADORA COUNTRY S.A.S | C24: BAPTISTE LIEVANO FELIPE | D24: KR 16 # 82 57 | E24: 6013905099 | F24: notificacionescdc@clinicadelcountry.com | H24: A · Lista (gerente+email) | I24: Email | J24: Por contactar
A25: 1100108064 | B25: ADN ANALISIS LTDA | C25: SALAZAR VALLEJO MARCELA | D25: CRA 16 # 82 95 CONS 805 | E25: 2364102 | F25: info@adnanalisislabs.com | G25: www.adnanalisislabs.com | H25: A · Lista (gerente+email) | I25: Email | J25: Por contactar
A26: 1100119508 | B26: ADRIANA CEBALLOS PORRAS E.U. | C26: ADRIANA CEBALLOS PORRAS | D26: DG 53 C N 23 - 44 LC 2 | E26: 3460502 | F26: elitedentalgalerias2008@hotmail.com | H26: A · Lista (gerente+email) | I26: Email | J26: Por contactar
A27: 110013994901 | B27: ADVANCEDERMA CLÍNICA DERMATOLÓGICA AVANZADA IPS S.A.S. Sigla: ADVANCEDERMA. | C27: LUIS FERNANDO GONZALEZ CORTES | D27: CRA 16 No. 88 - 81 OFI 707 - 708 - 709 | E27: 3043821546 | F27: LUISFER1000@GMAIL.COM | H27: A · Lista (gerente+email) | I27: Email | J27: Por contactar
A28: 110012806401 | B28: AEPSI SAS | C28: Yaquelin Huertas Paez | D28: Calle 93 B N° 16 - 08 consultorio 301 | E28: 3016260266 | F28: info@aepsi.com.co | H28: A · Lista (gerente+email) | I28: Email | J28: Por contactar
A29: 110013588302 | B29: AEQUI MOVISTAR | C29: Juliana Montenegro Castillo | D29: CALLE 63A 35 16 | E29: 3144394818 | F29: gerencia@aequi.com.co | H29: A · Lista (gerente+email) | I29: Email | J29: Por contactar
A30: 110013999501 | B30: AEQUSST MEDICINA PREVENTIVA SAS | C30: ADRIANA PRIETO CASTIBLANCO | D30: CALLE 18#9-20 LOCAL 405 | E30: 3102830124 | F30: notificaciones.aequsst@gmail.com | H30: A · Lista (gerente+email) | I30: Email | J30: Por contactar
A31: 110013863401 | B31: AEROMAS SAS | C31: MILLER AUGUSTO VARGAS ZAMORA | D31: Avenida Calle 26 113 81 Aeropuerto Internacional El Dorado En 6 Hg 15 Piso 1 Nzag | E31: 3175867106 | F31: habilitacion@aeromas.com.co | H31: A · Lista (gerente+email) | I31: Email | J31: Por contactar
A32: 110011627501 | B32: AESTHETIC MEDICAL SPA | C32: UMAR JOSE ABELLO RODRIGEZ | D32: KR 10 No. 96 - 25 CS 403 | E32: 6160557 | F32: aestheticmedical1@gmail.com | H32: A · Lista (gerente+email) | I32: Email | J32: Por contactar
A33: 110012139901 | B33: AG INSTITUTE CIRUGÍA PLÁSTICA, RECONSTRUCTIVA Y SALUD ESTETICA I.P.S. S.A.S | C33: JAMES ALEXIS ZAMBRANO HERNÁNDEZ | D33: Carrera 7 BIS No 124 - 26 Oficina 201 | E33: 7424270 | F33: contacto@alangonzalez.com | H33: A · Lista (gerente+email) | I33: Email | J33: Por contactar
A34: 110012223501 | B34: AGUA SPA ALEXANDRA GARCIA | C34: NELLY YADIRA DALEL MARTINEZ | D34: CRA 15 No. 134 -21 | E34: 3112500492 | F34: misapita1234@hotmail.com | H34: A · Lista (gerente+email) | I34: Email | J34: Por contactar
A35: 110013890201 | B35: AI-RAD | C35: MARIO ENRIQUE JOYA GALIANO | D35: Cr 19 A No 82-85 Consultorio 304 - 307 | E35: 3174379410 | F35: calidad@rimab.com.co | H35: A · Lista (gerente+email) | I35: Email | J35: Por contactar
A36: 110013561901 | B36: AIR LIQUIDE COLOMBIA AGENCIA LA CASTELLANA | C36: YESMIT JOHANNA ARCINIEGAS LADINO | D36: AK 45 # 94 23 TO A PI 2 | E36: 6017424444 | F36: calidad-salud@airliquide.com | H36: A · Lista (gerente+email) | I36: Email | J36: Por contactar
A37: 110013561902 | B37: AIR LIQUIDE COLOMBIA AGENCIA LAS AMERICAS | C37: PIERRE MARIE VALTON | D37: Carrera 44 No 14-95 P 2 | E37: 6017424444 | F37: calidad-salud@airliquide.com | H37: A · Lista (gerente+email) | I37: Email | J37: Por contactar
... A87: 110010562001 | B87: APRENDAMOS JUNTOS | C87: SEBASTIAN PELAEZ PEREZ | D87: CL 135A # 10 - 39 piso 1 | E87: 3047026 | F87: ajuntos2@gmail.com | H87: A · Lista (gerente+email) | I87: Email | J87: Por contactar
A88: 1100116660 | B88: ARCANGELES FUNDACION PARA LA REHABILITACION INTEGRAL | C88: JUAN PABLO SALAZAR SALAMANCA | D88: Cra 7 B bis# 132-38 Piso 9 y 10 Edificio Forest Medical Center | E88: 3336025204 | F88: direccionejecutiva@arcangeles.org | G88: www.arcangeles.org | H88: A · Lista (gerente+email) | I88: Email | J88: Por contactar
A89: 110014235201 | B89: ARCE 32 ALTA ESTÉTICA DENTAL S.A.S. | C89: LARRY ORTEGA JIMENEZ | D89: KR 12 No. 98 64 OF 507 ED. ALTHEA | E89: 3007315528 | F89: arce32dental@gmail.com | H89: A · Lista (gerente+email) | I89: Email | J89: Por contactar
A90: 110012075501 | B90: ARCHILA Y RICAURTE SAS | C90: MARIA DEL PILAR ARCHILA GOMEZ | D90: AK 7 N 119-14 CS 302 P3 | E90: 2152945 | F90: archilayricaurte@gmail.com | H90: A · Lista (gerente+email) | I90: Email | J90: Por contactar
A91: 110012731701 | B91: ARCOIRIS DE ESPERANZA S.A.S | C91: Lina Paola Bermudez Piñeros | D91: CARRERA 73 NUMERO 55 78 BARRIO NORMANDIA | E91: 3107732715/3143692116/6019158910 | F91: ipsade@arcoirisdeesperanza.com | H91: A · Lista (gerente+email) | I91: Email | J91: Por contactar
A92: 110012175901 | B92: ARIZALUD | C92: LUIS FERNANDO ARIZA HERNANDEZ | D92: TV 87 C # 59 A 23 SUR LC 1 | E92: 9231505-3228493476 | F92: arizalud@gmail.com | H92: A · Lista (gerente+email) | I92: Email | J92: Por contactar
A93: 110014048201 | B93: ARLETH BERNAL PSICOLOGÍA ESPECIALIZADA | C93: Emiro Jose Chica Quiñones | D93: Avenida Carrera 15 # 122 - 35 Consultorio 408 | E93: 3123954053 | F93: arlethpatriciab@gmail.com | H93: A · Lista (gerente+email) | I93: Email | J93: Por contactar
...
